Microsoft Windows [Version 10.0.19041.985]
(c) Microsoft Corporation. All rights reserved.

C:\Users\hp\Desktop\python_stack\python_stack>cd django

C:\Users\hp\Desktop\python_stack\python_stack\django>call djangoPy3Env/scripts/activate
(djangoPy3Env) C:\Users\hp\Desktop\python_stack\python_stack\django>cd django_orm

(djangoPy3Env) C:\Users\hp\Desktop\python_stack\python_stack\django\django_orm>django-admin startproject ninja_dojo

(djangoPy3Env) C:\Users\hp\Desktop\python_stack\python_stack\django\django_orm>cd ninja_dojo

(djangoPy3Env) C:\Users\hp\Desktop\python_stack\python_stack\django\django_orm\ninja_dojo>python manage.py runserver
Watching for file changes with StatReloader
Performing system checks...

System check identified no issues (0 silenced).

You have 17 unapplied migration(s). Your project may not work properly until you apply the migrations for app(s): admin, auth, contenttypes, sessions.
Run 'python manage.py migrate' to apply them.
May 22, 2021 - 22:40:06
Django version 2.2.4, using settings 'ninja_dojo.settings'
Starting development server at http://127.0.0.1:8000/
Quit the server with CTRL-BREAK.

(djangoPy3Env) C:\Users\hp\Desktop\python_stack\python_stack\django\django_orm\ninja_dojo>python manage.py startapp app_one

(djangoPy3Env) C:\Users\hp\Desktop\python_stack\python_stack\django\django_orm\ninja_dojo>coe .
'coe' is not recognized as an internal or external command,
operable program or batch file.

(djangoPy3Env) C:\Users\hp\Desktop\python_stack\python_stack\django\django_orm\ninja_dojo>code .

(djangoPy3Env) C:\Users\hp\Desktop\python_stack\python_stack\django\django_orm\ninja_dojo>python manage.py makemigrations
No changes detected

(djangoPy3Env) C:\Users\hp\Desktop\python_stack\python_stack\django\django_orm\ninja_dojo>python manage.py migrate
Operations to perform:
  Apply all migrations: admin, auth, contenttypes, sessions
Running migrations:
  Applying contenttypes.0001_initial... OK
  Applying auth.0001_initial... OK
  Applying admin.0001_initial... OK
  Applying admin.0002_logentry_remove_auto_add... OK
  Applying admin.0003_logentry_add_action_flag_choices... OK
  Applying contenttypes.0002_remove_content_type_name... OK
  Applying auth.0002_alter_permission_name_max_length... OK
  Applying auth.0003_alter_user_email_max_length... OK
  Applying auth.0004_alter_user_username_opts... OK
  Applying auth.0005_alter_user_last_login_null... OK
  Applying auth.0006_require_contenttypes_0002... OK
  Applying auth.0007_alter_validators_add_error_messages... OK
  Applying auth.0008_alter_user_username_max_length... OK
  Applying auth.0009_alter_user_last_name_max_length... OK
  Applying auth.0010_alter_group_name_max_length... OK
  Applying auth.0011_update_proxy_permissions... OK
  Applying sessions.0001_initial... OK

(djangoPy3Env) C:\Users\hp\Desktop\python_stack\python_stack\django\django_orm\ninja_dojo>python manage.py shell
Python 3.6.4 (v3.6.4:d48eceb, Dec 19 2017, 06:54:40) [MSC v.1900 64 bit (AMD64)] on win32
Type "help", "copyright", "credits" or "license" for more information.
(InteractiveConsole)
>>> exit ()

(djangoPy3Env) C:\Users\hp\Desktop\python_stack\python_stack\django\django_orm\ninja_dojo>python manage.py makemigrations
Traceback (most recent call last):
  File "manage.py", line 21, in <module>
    main()
  File "manage.py", line 17, in main
    execute_from_command_line(sys.argv)
  File "C:\Users\hp\Desktop\python_stack\python_stack\django\djangoPy3Env\lib\site-packages\django\core\management\__init__.py", line 381, in execute_from_command_line
    utility.execute()
  File "C:\Users\hp\Desktop\python_stack\python_stack\django\djangoPy3Env\lib\site-packages\django\core\management\__init__.py", line 357, in execute
    django.setup()
  File "C:\Users\hp\Desktop\python_stack\python_stack\django\djangoPy3Env\lib\site-packages\django\__init__.py", line 24, in setup
    apps.populate(settings.INSTALLED_APPS)
  File "C:\Users\hp\Desktop\python_stack\python_stack\django\djangoPy3Env\lib\site-packages\django\apps\registry.py", line 114, in populate
    app_config.import_models()
  File "C:\Users\hp\Desktop\python_stack\python_stack\django\djangoPy3Env\lib\site-packages\django\apps\config.py", line 211, in import_models
    self.models_module = import_module(models_module_name)
  File "C:\Users\hp\AppData\Local\Programs\Python\Python36\lib\importlib\__init__.py", line 126, in import_module
    return _bootstrap._gcd_import(name[level:], package, level)
  File "<frozen importlib._bootstrap>", line 994, in _gcd_import
  File "<frozen importlib._bootstrap>", line 971, in _find_and_load
  File "<frozen importlib._bootstrap>", line 955, in _find_and_load_unlocked
  File "<frozen importlib._bootstrap>", line 665, in _load_unlocked
  File "<frozen importlib._bootstrap_external>", line 678, in exec_module
  File "<frozen importlib._bootstrap>", line 219, in _call_with_frames_removed
  File "C:\Users\hp\Desktop\python_stack\python_stack\django\django_orm\ninja_dojo\app_one\models.py", line 3, in <module>
    class Ninja(models.Model):
  File "C:\Users\hp\Desktop\python_stack\python_stack\django\django_orm\ninja_dojo\app_one\models.py", line 6, in Ninja
    dojo= models.ForeignKey( Dojo, related_name="dojo", on_delete = models.CASCADE)
NameError: name 'Dojo' is not defined

(djangoPy3Env) C:\Users\hp\Desktop\python_stack\python_stack\django\django_orm\ninja_dojo>python manage.py makemigrations
Migrations for 'app_one':
  app_one\migrations\0001_initial.py
    - Create model Dojo
    - Create model Ninja

(djangoPy3Env) C:\Users\hp\Desktop\python_stack\python_stack\django\django_orm\ninja_dojo>python manage.py migrate
Operations to perform:
  Apply all migrations: admin, app_one, auth, contenttypes, sessions
Running migrations:
  Applying app_one.0001_initial... OK

(djangoPy3Env) C:\Users\hp\Desktop\python_stack\python_stack\django\django_orm\ninja_dojo>python manage.py shell
Python 3.6.4 (v3.6.4:d48eceb, Dec 19 2017, 06:54:40) [MSC v.1900 64 bit (AMD64)] on win32
Type "help", "copyright", "credits" or "license" for more information.
(InteractiveConsole)
>>> from app_one.models import *
>>> Dojo.objects.create(name = "jad", city = "ramallah" , state = "westbank")
<Dojo: Dojo object (1)>
>>> Dojo.objects.create(name = "lana", city = "ramallah" , state = "westbank")
<Dojo: Dojo object (2)>
>>> Dojo.objects.create(name = "ghazal", city = "betlehem" , state = "westbank")
<Dojo: Dojo object (3)>
>>> Dojo.objects.delete()
Traceback (most recent call last):
  File "<console>", line 1, in <module>
AttributeError: 'Manager' object has no attribute 'delete'
>>> Dojo.objects.dremove()
Traceback (most recent call last):
  File "<console>", line 1, in <module>
AttributeError: 'Manager' object has no attribute 'dremove'
>>> Dojo.objects.remove()
Traceback (most recent call last):
  File "<console>", line 1, in <module>
AttributeError: 'Manager' object has no attribute 'remove'
>>> dojo1 = Dojo.objects.get(id=1)
>>> dojo2 = Dojo.objects.get(id=2)
>>> dojo3 = Dojo.objects.get(id=3)
>>> Dojo.objects.remove(dojo1)
Traceback (most recent call last):
  File "<console>", line 1, in <module>
AttributeError: 'Manager' object has no attribute 'remove'
>>> exit ()

(djangoPy3Env) C:\Users\hp\Desktop\python_stack\python_stack\django\django_orm\ninja_dojo>python manage.py shell
Python 3.6.4 (v3.6.4:d48eceb, Dec 19 2017, 06:54:40) [MSC v.1900 64 bit (AMD64)] on win32
Type "help", "copyright", "credits" or "license" for more information.
(InteractiveConsole)
>>> dojo1.Dojo.remove(dojo1)
Traceback (most recent call last):
  File "<console>", line 1, in <module>
NameError: name 'dojo1' is not defined
>>> print(dojo1)
Traceback (most recent call last):
  File "<console>", line 1, in <module>
NameError: name 'dojo1' is not defined
>>> dojo1 = Dojo.objects.get(id=1)
Traceback (most recent call last):
  File "<console>", line 1, in <module>
NameError: name 'Dojo' is not defined
>>> from app_one.models import *
>>> Dojo.objects.remove(dojo1)
Traceback (most recent call last):
  File "<console>", line 1, in <module>
AttributeError: 'Manager' object has no attribute 'remove'
>>> dojo1 = Dojo.objects.get(id=1)
>>> dojo1.delete()
(1, {'app_one.Ninja': 0, 'app_one.Dojo': 1})
>>> dojo2.delete()
Traceback (most recent call last):
  File "<console>", line 1, in <module>
NameError: name 'dojo2' is not defined
>>> dojo2 = Dojo.objects.get(id=2)
>>> dojo3 = Dojo.objects.get(id=3)
>>> dojo2.delete()
(1, {'app_one.Ninja': 0, 'app_one.Dojo': 1})
>>> dojo3.delete()
(1, {'app_one.Ninja': 0, 'app_one.Dojo': 1})
>>> Dojo.objects.all().values()
<QuerySet []>
>>> Dojo.objects.create(name = "jad", city = "ramallah" , state = "westbank")
<Dojo: Dojo object (4)>
>>> Dojo.objects.create(name = "lana", city = "ramallah" , state = "westbank")
<Dojo: Dojo object (5)>
>>> Dojo.objects.create(name = "ghazal", city = "betlehem" , state = "westbank")
<Dojo: Dojo object (6)>
>>> dojo4 = Dojo.objects.get(id=4)
>>> dojo5 = Dojo.objects.get(id=5)
>>> dojo6 = Dojo.objects.get(id=6)
>>> Ninja.objects.create(first_name = "jad" , last_name = "dawani", dojo = dojo4)
<Ninja: Ninja object (1)>
>>> Ninja.objects.create(first_name = "lan" , last_name = "theo", dojo = dojo4)
<Ninja: Ninja object (2)>
>>> Ninja.objects.create(first_name = "ghazal" , last_name = "salameh", dojo = dojo4)
<Ninja: Ninja object (3)>
>>> Ninja.objects.create(first_name = "jaxd" , last_name = "dawanix", dojo = dojo5)
<Ninja: Ninja object (4)>
>>> Ninja.objects.create(first_name = "laxn" , last_name = "thexo", dojo = dojo5)
<Ninja: Ninja object (5)>
>>> Ninja.objects.create(first_name = "ghazaxl" , last_name = "salamexh", dojo = dojo5)
<Ninja: Ninja object (6)>
>>> Ninja.objects.create(first_name = "jax6d" , last_name = "dawani6x", dojo = dojo6)
<Ninja: Ninja object (7)>
>>> Ninja.objects.create(first_name = "ghazax6l" , last_name = "salamex6h", dojo = dojo6)
<Ninja: Ninja object (8)>
>>> Ninja.objects.create(first_name = "lax6n" , last_name = "thex6o", dojo = dojo6)
<Ninja: Ninja object (9)>
>>> dojo4.objects.all().values()
Traceback (most recent call last):
  File "<console>", line 1, in <module>
  File "C:\Users\hp\Desktop\python_stack\python_stack\django\djangoPy3Env\lib\site-packages\django\db\models\manager.py", line 176, in __get__
    raise AttributeError("Manager isn't accessible via %s instances" % cls.__name__)
AttributeError: Manager isn't accessible via Dojo instances
>>> Ninja.dojo4.all().values()
Traceback (most recent call last):
  File "<console>", line 1, in <module>
AttributeError: type object 'Ninja' has no attribute 'dojo4'
>>> Ninja.objects.all().values()
<QuerySet [{'id': 1, 'first_name': 'jad', 'last_name': 'dawani', 'dojo_id': 4, 'created_at': datetime.datetime(2021, 5, 22, 20, 35, 52, 308112, tzinfo=<UTC>), 'updated_at': datetime.datetime(2021, 5, 22, 20, 35, 52, 308112, tzinfo=<UTC>)}, {'id': 2, 'first_name': 'lan', 'last_name': 'theo', 'dojo_id': 4, 'created_at': datetime.datetime(2021, 5, 22, 20, 36, 17, 226997, tzinfo=<UTC>), 'updated_at': datetime.datetime(2021, 5, 22, 20, 36, 17, 228000, tzinfo=<UTC>)}, {'id': 3, 'first_name': 'ghazal', 'last_name': 'salameh', 'dojo_id': 4, 'created_at': datetime.datetime(2021, 5, 22, 20, 37, 41, 35045, tzinfo=<UTC>), 'updated_at': datetime.datetime(2021, 5, 22, 20, 37, 41, 36039, tzinfo=<UTC>)}, {'id': 4, 'first_name': 'jaxd', 'last_name': 'dawanix', 'dojo_id': 5, 'created_at': datetime.datetime(2021, 5, 22, 20, 47, 10, 468092, tzinfo=<UTC>), 'updated_at': datetime.datetime(2021, 5, 22, 20, 47, 10, 468092, tzinfo=<UTC>)}, {'id': 5, 'first_name': 'laxn', 'last_name': 'thexo', 'dojo_id': 5, 'created_at': datetime.datetime(2021, 5, 22, 20, 47, 46, 667614, tzinfo=<UTC>), 'updated_at': datetime.datetime(2021, 5, 22, 20, 47, 46, 667614, tzinfo=<UTC>)}, {'id': 6, 'first_name': 'ghazaxl', 'last_name': 'salamexh', 'dojo_id': 5, 'created_at': datetime.datetime(2021, 5, 22, 20, 48, 3, 171103, tzinfo=<UTC>), 'updated_at': datetime.datetime(2021, 5, 22, 20, 48, 3, 172110, tzinfo=<UTC>)}, {'id': 7, 'first_name': 'jax6d', 'last_name': 'dawani6x', 'dojo_id': 6, 'created_at': datetime.datetime(2021, 5, 22, 20, 48, 22, 507176, tzinfo=<UTC>), 'updated_at': datetime.datetime(2021, 5, 22, 20, 48, 22, 508180, tzinfo=<UTC>)}, {'id': 8, 'first_name': 'ghazax6l', 'last_name': 'salamex6h', 'dojo_id': 6, 'created_at': datetime.datetime(2021, 5, 22, 20, 48, 38, 51057, tzinfo=<UTC>), 'updated_at': datetime.datetime(2021, 5, 22, 20, 48, 38, 52059, tzinfo=<UTC>)}, {'id': 9, 'first_name': 'lax6n', 'last_name': 'thex6o', 'dojo_id': 6, 'created_at': datetime.datetime(2021, 5, 22, 20, 48, 56, 875430, tzinfo=<UTC>), 'updated_at': datetime.datetime(2021, 5, 22, 20, 48, 56, 875430, tzinfo=<UTC>)}]>
>>> books = Ninja.objects.filter(dojo=Dojo.objects.get(id=1))
Traceback (most recent call last):
  File "<console>", line 1, in <module>
  File "C:\Users\hp\Desktop\python_stack\python_stack\django\djangoPy3Env\lib\site-packages\django\db\models\manager.py", line 82, in manager_method
    return getattr(self.get_queryset(), name)(*args, **kwargs)
  File "C:\Users\hp\Desktop\python_stack\python_stack\django\djangoPy3Env\lib\site-packages\django\db\models\query.py", line 408, in get
    self.model._meta.object_name
app_one.models.Dojo.DoesNotExist: Dojo matching query does not exist.
>>> books = Ninja.objects.filter(dojo= Ninja.objects.get(id=1))
Traceback (most recent call last):
  File "<console>", line 1, in <module>
  File "C:\Users\hp\Desktop\python_stack\python_stack\django\djangoPy3Env\lib\site-packages\django\db\models\manager.py", line 82, in manager_method
    return getattr(self.get_queryset(), name)(*args, **kwargs)
  File "C:\Users\hp\Desktop\python_stack\python_stack\django\djangoPy3Env\lib\site-packages\django\db\models\query.py", line 892, in filter
    return self._filter_or_exclude(False, *args, **kwargs)
  File "C:\Users\hp\Desktop\python_stack\python_stack\django\djangoPy3Env\lib\site-packages\django\db\models\query.py", line 910, in _filter_or_exclude
    clone.query.add_q(Q(*args, **kwargs))
  File "C:\Users\hp\Desktop\python_stack\python_stack\django\djangoPy3Env\lib\site-packages\django\db\models\sql\query.py", line 1290, in add_q
    clause, _ = self._add_q(q_object, self.used_aliases)
  File "C:\Users\hp\Desktop\python_stack\python_stack\django\djangoPy3Env\lib\site-packages\django\db\models\sql\query.py", line 1318, in _add_q
    split_subq=split_subq, simple_col=simple_col,
  File "C:\Users\hp\Desktop\python_stack\python_stack\django\djangoPy3Env\lib\site-packages\django\db\models\sql\query.py", line 1224, in build_filter
    self.check_related_objects(join_info.final_field, value, join_info.opts)
  File "C:\Users\hp\Desktop\python_stack\python_stack\django\djangoPy3Env\lib\site-packages\django\db\models\sql\query.py", line 1084, in check_related_objects
    self.check_query_object_type(value, opts, field)
  File "C:\Users\hp\Desktop\python_stack\python_stack\django\djangoPy3Env\lib\site-packages\django\db\models\sql\query.py", line 1067, in check_query_object_type
    (value, opts.object_name))
ValueError: Cannot query "Ninja object (1)": Must be "Dojo" instance.
>>> books = Ninja.objects.filter(dojo=Dojo.objects.get(id=4))
>>> print(books)
<QuerySet [<Ninja: Ninja object (1)>, <Ninja: Ninja object (2)>, <Ninja: Ninja object (3)>]>
>>> books2 = Ninja.objects.filter(dojo=Dojo.objects.last())
>>> print(books2)
<QuerySet [<Ninja: Ninja object (7)>, <Ninja: Ninja object (8)>, <Ninja: Ninja object (9)>]>
>>> books3 = Ninja.objects.last().values()
Traceback (most recent call last):
  File "<console>", line 1, in <module>
AttributeError: 'Ninja' object has no attribute 'values'
>>> books3 = Ninja.objects.last()
>>> print(books3)
Ninja object (9)
>>> books4 = Ninja.objects.last().filter(dojo = Dojo.objects.all().values())
Traceback (most recent call last):
  File "<console>", line 1, in <module>
AttributeError: 'Ninja' object has no attribute 'filter'
>>> books4 = Ninja.objects.get(id = 9)
>>> books4 = Ninja.objects.get(id = 9).all()
Traceback (most recent call last):
  File "<console>", line 1, in <module>
AttributeError: 'Ninja' object has no attribute 'all'
>>> books4 = Ninja.objects.get(id = 9)
>>> print(book4)
Traceback (most recent call last):
  File "<console>", line 1, in <module>
NameError: name 'book4' is not defined
>>> print(books4)
Ninja object (9)
>>> books4.objects.all().values()
Traceback (most recent call last):
  File "<console>", line 1, in <module>
  File "C:\Users\hp\Desktop\python_stack\python_stack\django\djangoPy3Env\lib\site-packages\django\db\models\manager.py", line 176, in __get__
    raise AttributeError("Manager isn't accessible via %s instances" % cls.__name__)
AttributeError: Manager isn't accessible via Ninja instances
>>> books4.dojo
<Dojo: Dojo object (6)>
>>> exit()

(djangoPy3Env) C:\Users\hp\Desktop\python_stack\python_stack\django\django_orm\ninja_dojo>python manage.py makemigrations
Migrations for 'app_one':
  app_one\migrations\0002_dojo_desc.py
    - Add field desc to dojo

(djangoPy3Env) C:\Users\hp\Desktop\python_stack\python_stack\django\django_orm\ninja_dojo>python manage.py migrate
Operations to perform:
  Apply all migrations: admin, app_one, auth, contenttypes, sessions
Running migrations:
  Applying app_one.0002_dojo_desc... OK

(djangoPy3Env) C:\Users\hp\Desktop\python_stack\python_stack\django\django_orm\ninja_dojo>python manage.py shell
Python 3.6.4 (v3.6.4:d48eceb, Dec 19 2017, 06:54:40) [MSC v.1900 64 bit (AMD64)] on win32
Type "help", "copyright", "credits" or "license" for more information.
(InteractiveConsole)
