Microsoft Windows [Version 10.0.19041.985]
(c) Microsoft Corporation. All rights reserved.

C:\Users\hp\Desktop\python_stack\python_stack\_python\Flask>cd ..

C:\Users\hp\Desktop\python_stack\python_stack\_python>cd ..

C:\Users\hp\Desktop\python_stack\python_stack>cd django

C:\Users\hp\Desktop\python_stack\python_stack\django>call djangoPy3Env/scripts/activate
(djangoPy3Env) C:\Users\hp\Desktop\python_stack\python_stack\django>cd django_orm

(djangoPy3Env) C:\Users\hp\Desktop\python_stack\python_stack\django\django_orm>django-admin startproject Users

(djangoPy3Env) C:\Users\hp\Desktop\python_stack\python_stack\django\django_orm>cd Users

(djangoPy3Env) C:\Users\hp\Desktop\python_stack\python_stack\django\django_orm\Users>pyhton manage.py runserver
'pyhton' is not recognized as an internal or external command,
operable program or batch file.

(djangoPy3Env) C:\Users\hp\Desktop\python_stack\python_stack\django\django_orm\Users>python manage.py runserver
Watching for file changes with StatReloader
Performing system checks...

System check identified no issues (0 silenced).

You have 17 unapplied migration(s). Your project may not work properly until you apply the migrations for app(s): admin, auth, contenttypes, sessions.
Run 'python manage.py migrate' to apply them.
May 20, 2021 - 11:03:15
Django version 2.2.4, using settings 'Users.settings'
Starting development server at http://127.0.0.1:8000/
Quit the server with CTRL-BREAK.

(djangoPy3Env) C:\Users\hp\Desktop\python_stack\python_stack\django\django_orm\Users>python manage.py makemigrations
No changes detected

(djangoPy3Env) C:\Users\hp\Desktop\python_stack\python_stack\django\django_orm\Users>python manage.py migrate
Operations to perform:
  Apply all migrations: admin, auth, contenttypes, sessions
Running migrations:
  Applying contenttypes.0001_initial... OK
  Applying auth.0001_initial... OK
  Applying admin.0001_initial... OK
  Applying admin.0002_logentry_remove_auto_add... OK
  Applying admin.0003_logentry_add_action_flag_choices... OK
  Applying contenttypes.0002_remove_content_type_name... OK
  Applying auth.0002_alter_permission_name_max_length... OK
  Applying auth.0003_alter_user_email_max_length... OK
  Applying auth.0004_alter_user_username_opts... OK
  Applying auth.0005_alter_user_last_login_null... OK
  Applying auth.0006_require_contenttypes_0002... OK
  Applying auth.0007_alter_validators_add_error_messages... OK
  Applying auth.0008_alter_user_username_max_length... OK
  Applying auth.0009_alter_user_last_name_max_length... OK
  Applying auth.0010_alter_group_name_max_length... OK
  Applying auth.0011_update_proxy_permissions... OK
  Applying sessions.0001_initial... OK

(djangoPy3Env) C:\Users\hp\Desktop\python_stack\python_stack\django\django_orm\Users>python manage.py startapp usersapp

(djangoPy3Env) C:\Users\hp\Desktop\python_stack\python_stack\django\django_orm\Users>python manage.py makemigrations
Migrations for 'usersapp':
  usersapp\migrations\0001_initial.py
    - Create model Moviecopy

(djangoPy3Env) C:\Users\hp\Desktop\python_stack\python_stack\django\django_orm\Users>python manage.py migrate
Operations to perform:
  Apply all migrations: admin, auth, contenttypes, sessions, usersapp
Running migrations:
  Applying usersapp.0001_initial... OK

(djangoPy3Env) C:\Users\hp\Desktop\python_stack\python_stack\django\django_orm\Users>pyhton manage.py runserver
'pyhton' is not recognized as an internal or external command,
operable program or batch file.

(djangoPy3Env) C:\Users\hp\Desktop\python_stack\python_stack\django\django_orm\Users>python manage.py runserver
Watching for file changes with StatReloader
Performing system checks...

System check identified no issues (0 silenced).
May 20, 2021 - 11:37:22
Django version 2.2.4, using settings 'Users.settings'
Starting development server at http://127.0.0.1:8000/
Quit the server with CTRL-BREAK.

(djangoPy3Env) C:\Users\hp\Desktop\python_stack\python_stack\django\django_orm\Users>python manage.py shell
Python 3.6.4 (v3.6.4:d48eceb, Dec 19 2017, 06:54:40) [MSC v.1900 64 bit (AMD64)] on win32
Type "help", "copyright", "credits" or "license" for more information.
(InteractiveConsole)
>>> from usersapp.models import *
>>> users.objects.create(first_name = "lana", last_name = "theo", age = "8-2-2000", email = "la@th")
Traceback (most recent call last):
  File "<console>", line 1, in <module>
NameError: name 'users' is not defined
>>>
KeyboardInterrupt
>>> exit ()

(djangoPy3Env) C:\Users\hp\Desktop\python_stack\python_stack\django\django_orm\Users>python manage.py makemigrations
Did you rename the usersapp.Moviecopy model to users? [y/N]
Migrations for 'usersapp':
  usersapp\migrations\0002_auto_20210520_1143.py
    - Create model users
    - Delete model Moviecopy

(djangoPy3Env) C:\Users\hp\Desktop\python_stack\python_stack\django\django_orm\Users>y
'y' is not recognized as an internal or external command,
operable program or batch file.

(djangoPy3Env) C:\Users\hp\Desktop\python_stack\python_stack\django\django_orm\Users>python manage.py makemigrations
No changes detected

(djangoPy3Env) C:\Users\hp\Desktop\python_stack\python_stack\django\django_orm\Users>python manage.py migrate
Operations to perform:
  Apply all migrations: admin, auth, contenttypes, sessions, usersapp
Running migrations:
  Applying usersapp.0002_auto_20210520_1143... OK

(djangoPy3Env) C:\Users\hp\Desktop\python_stack\python_stack\django\django_orm\Users>python manage.py shell
Python 3.6.4 (v3.6.4:d48eceb, Dec 19 2017, 06:54:40) [MSC v.1900 64 bit (AMD64)] on win32
Type "help", "copyright", "credits" or "license" for more information.
(InteractiveConsole)
>>> users.objects.create(first_name = "lana", last_name = "theo", age = "8-2-2000", email = "la@th")
Traceback (most recent call last):
  File "<console>", line 1, in <module>
NameError: name 'users' is not defined
>>> exit ()

(djangoPy3Env) C:\Users\hp\Desktop\python_stack\python_stack\django\django_orm\Users>python manage.py runserver
Watching for file changes with StatReloader
Performing system checks...

System check identified no issues (0 silenced).
May 20, 2021 - 11:45:45
Django version 2.2.4, using settings 'Users.settings'
Starting development server at http://127.0.0.1:8000/
Quit the server with CTRL-BREAK.

(djangoPy3Env) C:\Users\hp\Desktop\python_stack\python_stack\django\django_orm\Users>python manage.py makemigrations
No changes detected

(djangoPy3Env) C:\Users\hp\Desktop\python_stack\python_stack\django\django_orm\Users>python manage.py migrate
Operations to perform:
  Apply all migrations: admin, auth, contenttypes, sessions, usersapp
Running migrations:
  No migrations to apply.

(djangoPy3Env) C:\Users\hp\Desktop\python_stack\python_stack\django\django_orm\Users>pyhton manage.py shell
'pyhton' is not recognized as an internal or external command,
operable program or batch file.

(djangoPy3Env) C:\Users\hp\Desktop\python_stack\python_stack\django\django_orm\Users>python manage.py shell
Python 3.6.4 (v3.6.4:d48eceb, Dec 19 2017, 06:54:40) [MSC v.1900 64 bit (AMD64)] on win32
Type "help", "copyright", "credits" or "license" for more information.
(InteractiveConsole)
>>> users.objects.create(first_name = "lana", last_name = "theo", age = "8-2-2000", email = "la@th")
Traceback (most recent call last):
  File "<console>", line 1, in <module>
NameError: name 'users' is not defined
>>> from usersapp.models import *
>>> users.objects.create(first_name = "lana", last_name = "theo", age = "8-2-2000", email = "la@th")
Traceback (most recent call last):
  File "<console>", line 1, in <module>
  File "C:\Users\hp\Desktop\python_stack\python_stack\django\djangoPy3Env\lib\site-packages\django\db\models\manager.py", line 82, in manager_method
    return getattr(self.get_queryset(), name)(*args, **kwargs)
  File "C:\Users\hp\Desktop\python_stack\python_stack\django\djangoPy3Env\lib\site-packages\django\db\models\query.py", line 422, in create
    obj.save(force_insert=True, using=self.db)
  File "C:\Users\hp\Desktop\python_stack\python_stack\django\djangoPy3Env\lib\site-packages\django\db\models\base.py", line 741, in save
    force_update=force_update, update_fields=update_fields)
  File "C:\Users\hp\Desktop\python_stack\python_stack\django\djangoPy3Env\lib\site-packages\django\db\models\base.py", line 779, in save_base
    force_update, using, update_fields,
  File "C:\Users\hp\Desktop\python_stack\python_stack\django\djangoPy3Env\lib\site-packages\django\db\models\base.py", line 870, in _save_table
    result = self._do_insert(cls._base_manager, using, fields, update_pk, raw)
  File "C:\Users\hp\Desktop\python_stack\python_stack\django\djangoPy3Env\lib\site-packages\django\db\models\base.py", line 908, in _do_insert
    using=using, raw=raw)
  File "C:\Users\hp\Desktop\python_stack\python_stack\django\djangoPy3Env\lib\site-packages\django\db\models\manager.py", line 82, in manager_method
    return getattr(self.get_queryset(), name)(*args, **kwargs)
  File "C:\Users\hp\Desktop\python_stack\python_stack\django\djangoPy3Env\lib\site-packages\django\db\models\query.py", line 1186, in _insert
    return query.get_compiler(using=using).execute_sql(return_id)
  File "C:\Users\hp\Desktop\python_stack\python_stack\django\djangoPy3Env\lib\site-packages\django\db\models\sql\compiler.py", line 1334, in execute_sql
    for sql, params in self.as_sql():
  File "C:\Users\hp\Desktop\python_stack\python_stack\django\djangoPy3Env\lib\site-packages\django\db\models\sql\compiler.py", line 1278, in as_sql
    for obj in self.query.objs
  File "C:\Users\hp\Desktop\python_stack\python_stack\django\djangoPy3Env\lib\site-packages\django\db\models\sql\compiler.py", line 1278, in <listcomp>
    for obj in self.query.objs
  File "C:\Users\hp\Desktop\python_stack\python_stack\django\djangoPy3Env\lib\site-packages\django\db\models\sql\compiler.py", line 1277, in <listcomp>
    [self.prepare_value(field, self.pre_save_val(field, obj)) for field in fields]
  File "C:\Users\hp\Desktop\python_stack\python_stack\django\djangoPy3Env\lib\site-packages\django\db\models\sql\compiler.py", line 1218, in prepare_value
    value = field.get_db_prep_save(value, connection=self.connection)
  File "C:\Users\hp\Desktop\python_stack\python_stack\django\djangoPy3Env\lib\site-packages\django\db\models\fields\__init__.py", line 789, in get_db_prep_save
    return self.get_db_prep_value(value, connection=connection, prepared=False)
  File "C:\Users\hp\Desktop\python_stack\python_stack\django\djangoPy3Env\lib\site-packages\django\db\models\fields\__init__.py", line 1273, in get_db_prep_value
    value = self.get_prep_value(value)
  File "C:\Users\hp\Desktop\python_stack\python_stack\django\djangoPy3Env\lib\site-packages\django\db\models\fields\__init__.py", line 1268, in get_prep_value
    return self.to_python(value)
  File "C:\Users\hp\Desktop\python_stack\python_stack\django\djangoPy3Env\lib\site-packages\django\db\models\fields\__init__.py", line 1243, in to_python
    params={'value': value},
django.core.exceptions.ValidationError: ["'8-2-2000' value has an invalid date format. It must be in YYYY-MM-DD format."]
>>>
KeyboardInterrupt
>>> exit ()

(djangoPy3Env) C:\Users\hp\Desktop\python_stack\python_stack\django\django_orm\Users>python manage.py makemigrations
Migrations for 'usersapp':
  usersapp\migrations\0003_auto_20210520_1149.py
    - Alter field age on users

(djangoPy3Env) C:\Users\hp\Desktop\python_stack\python_stack\django\django_orm\Users>python manage.py migrate
Operations to perform:
  Apply all migrations: admin, auth, contenttypes, sessions, usersapp
Running migrations:
  Applying usersapp.0003_auto_20210520_1149... OK

(djangoPy3Env) C:\Users\hp\Desktop\python_stack\python_stack\django\django_orm\Users>python manage.py shell
Python 3.6.4 (v3.6.4:d48eceb, Dec 19 2017, 06:54:40) [MSC v.1900 64 bit (AMD64)] on win32
Type "help", "copyright", "credits" or "license" for more information.
(InteractiveConsole)
>>> from usersapp.models import *
>>> users.objects.create(first_name = "lana", last_name = "theo", age = "21", email = "la@th")
<users: users object (1)>
>>> users.objects.create(first_name = "ghaith", last_name = "assaf", age = "27", email = "la@th")
<users: users object (2)>
>>> users.objects.create(first_name = "laxx", last_name = "xtxheo", age = "8", email = "la@th")
<users: users object (3)>
>>> usersapp.objects.all()
Traceback (most recent call last):
  File "<console>", line 1, in <module>
NameError: name 'usersapp' is not defined
>>> users.objects.all()
<QuerySet [<users: users object (1)>, <users: users object (2)>, <users: users object (3)>]>
>>> users.objects.all().values()
<QuerySet [{'id': 1, 'first_name': 'lana', 'last_name': 'theo', 'age': 21, 'email': 'la@th', 'created_at': datetime.datetime(2021, 5, 20, 8, 50, 56, 373765, tzinfo=<UTC>), 'updated_at': datetime.datetime(2021, 5, 20, 8, 50, 56, 373765, tzinfo=<UTC>)}, {'id': 2, 'first_name': 'ghaith', 'last_name': 'assaf', 'age': 27, 'email': 'la@th', 'created_at': datetime.datetime(2021, 5, 20, 8, 51, 39, 401803, tzinfo=<UTC>), 'updated_at': datetime.datetime(2021, 5, 20, 8, 51, 39, 401803, tzinfo=<UTC>)}, {'id': 3, 'first_name': 'laxx', 'last_name': 'xtxheo', 'age': 8, 'email': 'la@th', 'created_at': datetime.datetime(2021, 5, 20, 8, 52, 5, 698030, tzinfo=<UTC>), 'updated_at': datetime.datetime(2021, 5, 20, 8, 52, 5, 698030, tzinfo=<UTC>)}]>
>>> users.objects.last()
<users: users object (3)>
>>> users.objects.last().values()
Traceback (most recent call last):
  File "<console>", line 1, in <module>
AttributeError: 'users' object has no attribute 'values'
>>> users.objects.values().last()
{'id': 3, 'first_name': 'laxx', 'last_name': 'xtxheo', 'age': 8, 'email': 'la@th', 'created_at': datetime.datetime(2021, 5, 20, 8, 52, 5, 698030, tzinfo=<UTC>), 'updated_at': datetime.datetime(2021, 5, 20, 8, 52, 5, 698030, tzinfo=<UTC>)}
>>> users.objects.values().first()
{'id': 1, 'first_name': 'lana', 'last_name': 'theo', 'age': 21, 'email': 'la@th', 'created_at': datetime.datetime(2021, 5, 20, 8, 50, 56, 373765, tzinfo=<UTC>), 'updated_at': datetime.datetime(2021, 5, 20, 8, 50, 56, 373765, tzinfo=<UTC>)}
>>> users.objects.get(id=3).last_name = "pancakes"
>>> users.objects.get(id=3).last_name.save()
Traceback (most recent call last):
  File "<console>", line 1, in <module>
AttributeError: 'str' object has no attribute 'save'
>>> users.objects.get(id=3).save()
>>> users.objects.values().last()
{'id': 3, 'first_name': 'laxx', 'last_name': 'xtxheo', 'age': 8, 'email': 'la@th', 'created_at': datetime.datetime(2021, 5, 20, 8, 52, 5, 698030, tzinfo=<UTC>), 'updated_at': datetime.datetime(2021, 5, 20, 8, 58, 54, 431061, tzinfo=<UTC>)}
>>> x = users.objects.get(id=3)
>>> x.last_name = "pancakes"
>>> x.save()
>>> users.objects.values().last()
{'id': 3, 'first_name': 'laxx', 'last_name': 'pancakes', 'age': 8, 'email': 'la@th', 'created_at': datetime.datetime(2021, 5, 20, 8, 52, 5, 698030, tzinfo=<UTC>), 'updated_at': datetime.datetime(2021, 5, 20, 9, 0, 57, 245019, tzinfo=<UTC>)}
>>> c = users.objects.get(id=2)
>>> c.delete()
(1, {'usersapp.users': 1})
>>> users.objects.values()
<QuerySet [{'id': 1, 'first_name': 'lana', 'last_name': 'theo', 'age': 21, 'email': 'la@th', 'created_at': datetime.datetime(2021, 5, 20, 8, 50, 56, 373765, tzinfo=<UTC>), 'updated_at': datetime.datetime(2021, 5, 20, 8, 50, 56, 373765, tzinfo=<UTC>)}, {'id': 3, 'first_name': 'laxx', 'last_name': 'pancakes', 'age': 8, 'email': 'la@th', 'created_at': datetime.datetime(2021, 5, 20, 8, 52, 5, 698030, tzinfo=<UTC>), 'updated_at': datetime.datetime(2021, 5, 20, 9, 0, 57, 245019, tzinfo=<UTC>)}]>
>>> users.objects.all().order_by("first_name")
<QuerySet [<users: users object (1)>, <users: users object (3)>]>
>>> users.objects.all().order_by("-first_name")
<QuerySet [<users: users object (3)>, <users: users object (1)>]>
>>>